[2025-07-21T03:20:50.016+0000] {local_task_job_runner.py:120} INFO - ::group::Pre task execution logs
[2025-07-21T03:20:50.043+0000] {taskinstance.py:2076} INFO - Dependencies all met for dep_context=non-requeueable deps ti=<TaskInstance: fetch_weather_foreacst_dag.fetch_forecast manual__2025-07-21T03:20:47.550372+00:00 [queued]>
[2025-07-21T03:20:50.052+0000] {taskinstance.py:2076} INFO - Dependencies all met for dep_context=requeueable deps ti=<TaskInstance: fetch_weather_foreacst_dag.fetch_forecast manual__2025-07-21T03:20:47.550372+00:00 [queued]>
[2025-07-21T03:20:50.053+0000] {taskinstance.py:2306} INFO - Starting attempt 1 of 3
[2025-07-21T03:20:50.065+0000] {taskinstance.py:2330} INFO - Executing <Task(PythonOperator): fetch_forecast> on 2025-07-21 03:20:47.550372+00:00
[2025-07-21T03:20:50.072+0000] {standard_task_runner.py:90} INFO - Running: ['***', 'tasks', 'run', 'fetch_weather_foreacst_dag', 'fetch_forecast', 'manual__2025-07-21T03:20:47.550372+00:00', '--job-id', '71', '--raw', '--subdir', 'DAGS_FOLDER/weather_dag.py', '--cfg-path', '/tmp/tmp44grbev2']
[2025-07-21T03:20:50.074+0000] {logging_mixin.py:188} WARNING - /home/***/.local/lib/python3.12/site-packages/***/task/task_runner/standard_task_runner.py:61 DeprecationWarning: This process (pid=190) is multi-threaded, use of fork() may lead to deadlocks in the child.
[2025-07-21T03:20:50.074+0000] {standard_task_runner.py:91} INFO - Job 71: Subtask fetch_forecast
[2025-07-21T03:20:50.075+0000] {standard_task_runner.py:63} INFO - Started process 192 to run task
[2025-07-21T03:20:50.118+0000] {task_command.py:426} INFO - Running <TaskInstance: fetch_weather_foreacst_dag.fetch_forecast manual__2025-07-21T03:20:47.550372+00:00 [running]> on host a689e5446531
[2025-07-21T03:20:50.192+0000] {taskinstance.py:2648} INFO - Exporting env vars: AIRFLOW_CTX_DAG_OWNER='***' AIRFLOW_CTX_DAG_ID='fetch_weather_foreacst_dag' AIRFLOW_CTX_TASK_ID='fetch_forecast' AIRFLOW_CTX_EXECUTION_DATE='2025-07-21T03:20:47.550372+00:00' AIRFLOW_CTX_TRY_NUMBER='1' AIRFLOW_CTX_DAG_RUN_ID='manual__2025-07-21T03:20:47.550372+00:00'
[2025-07-21T03:20:50.193+0000] {taskinstance.py:430} INFO - ::endgroup::
[2025-07-21T03:20:50.204+0000] {weather_dag.py:49} INFO - Bắt đầu gọi API thời tiết...
[2025-07-21T03:20:50.736+0000] {weather_dag.py:81} WARNING - Rate limit cho Ho Chi Minh. Bỏ qua
[2025-07-21T03:20:51.201+0000] {weather_dag.py:81} WARNING - Rate limit cho Ha Noi. Bỏ qua
[2025-07-21T03:20:51.690+0000] {weather_dag.py:81} WARNING - Rate limit cho Da Nang. Bỏ qua
[2025-07-21T03:20:52.124+0000] {weather_dag.py:81} WARNING - Rate limit cho Hue. Bỏ qua
[2025-07-21T03:20:52.574+0000] {weather_dag.py:81} WARNING - Rate limit cho Hai Phong. Bỏ qua
[2025-07-21T03:20:53.027+0000] {weather_dag.py:81} WARNING - Rate limit cho Can Tho. Bỏ qua
[2025-07-21T03:20:53.535+0000] {weather_dag.py:81} WARNING - Rate limit cho Bien Hoa. Bỏ qua
[2025-07-21T03:20:54.002+0000] {weather_dag.py:81} WARNING - Rate limit cho Quang Ninh. Bỏ qua
[2025-07-21T03:20:54.424+0000] {weather_dag.py:81} WARNING - Rate limit cho Nghe An. Bỏ qua
[2025-07-21T03:20:54.875+0000] {weather_dag.py:81} WARNING - Rate limit cho Ninh Binh. Bỏ qua
[2025-07-21T03:20:54.876+0000] {taskinstance.py:441} INFO - ::group::Post task execution logs
[2025-07-21T03:20:54.877+0000] {taskinstance.py:2905} ERROR - Task failed with exception
Traceback (most recent call last):
  File "/home/airflow/.local/lib/python3.12/site-packages/airflow/models/taskinstance.py", line 465, in _execute_task
    result = _execute_callable(context=context, **execute_callable_kwargs)
             ^^^^^^^^^^^^^^^^^^^^^^^^^^^^^^^^^^^^^^^^^^^^^^^^^^^^^^^^^^^^^
  File "/home/airflow/.local/lib/python3.12/site-packages/airflow/models/taskinstance.py", line 432, in _execute_callable
    return execute_callable(context=context, **execute_callable_kwargs)
           ^^^^^^^^^^^^^^^^^^^^^^^^^^^^^^^^^^^^^^^^^^^^^^^^^^^^^^^^^^^^
  File "/home/airflow/.local/lib/python3.12/site-packages/airflow/models/baseoperator.py", line 401, in wrapper
    return func(self, *args, **kwargs)
           ^^^^^^^^^^^^^^^^^^^^^^^^^^^
  File "/home/airflow/.local/lib/python3.12/site-packages/airflow/operators/python.py", line 235, in execute
    return_value = self.execute_callable()
                   ^^^^^^^^^^^^^^^^^^^^^^^
  File "/home/airflow/.local/lib/python3.12/site-packages/airflow/operators/python.py", line 252, in execute_callable
    return self.python_callable(*self.op_args, **self.op_kwargs)
           ^^^^^^^^^^^^^^^^^^^^^^^^^^^^^^^^^^^^^^^^^^^^^^^^^^^^^
  File "/opt/airflow/dags/weather_dag.py", line 90, in fetch_weather_data
    raise ValueError(" Không có dữ liệu nào được lấy từ API. Dừng pipeline để tránh lỗi tiếp theo.")
ValueError:  Không có dữ liệu nào được lấy từ API. Dừng pipeline để tránh lỗi tiếp theo.
[2025-07-21T03:20:54.888+0000] {taskinstance.py:1206} INFO - Marking task as UP_FOR_RETRY. dag_id=fetch_weather_foreacst_dag, task_id=fetch_forecast, run_id=manual__2025-07-21T03:20:47.550372+00:00, execution_date=20250721T032047, start_date=20250721T032050, end_date=20250721T032054
[2025-07-21T03:20:54.900+0000] {standard_task_runner.py:110} ERROR - Failed to execute job 71 for task fetch_forecast ( Không có dữ liệu nào được lấy từ API. Dừng pipeline để tránh lỗi tiếp theo.; 192)
[2025-07-21T03:20:54.914+0000] {local_task_job_runner.py:240} INFO - Task exited with return code 1
[2025-07-21T03:20:54.929+0000] {taskinstance.py:3503} INFO - 0 downstream tasks scheduled from follow-on schedule check
[2025-07-21T03:20:54.930+0000] {local_task_job_runner.py:222} INFO - ::endgroup::
