[2025-07-21T07:41:15.539+0000] {local_task_job_runner.py:120} INFO - ::group::Pre task execution logs
[2025-07-21T07:41:15.563+0000] {taskinstance.py:2076} INFO - Dependencies all met for dep_context=non-requeueable deps ti=<TaskInstance: fetch_weather_foreacst_dag.create_staging_table scheduled__2025-07-21T00:00:00+00:00 [queued]>
[2025-07-21T07:41:15.569+0000] {taskinstance.py:2076} INFO - Dependencies all met for dep_context=requeueable deps ti=<TaskInstance: fetch_weather_foreacst_dag.create_staging_table scheduled__2025-07-21T00:00:00+00:00 [queued]>
[2025-07-21T07:41:15.570+0000] {taskinstance.py:2306} INFO - Starting attempt 2 of 3
[2025-07-21T07:41:15.580+0000] {taskinstance.py:2330} INFO - Executing <Task(PythonOperator): create_staging_table> on 2025-07-21 00:00:00+00:00
[2025-07-21T07:41:15.587+0000] {standard_task_runner.py:90} INFO - Running: ['***', 'tasks', 'run', 'fetch_weather_foreacst_dag', 'create_staging_table', 'scheduled__2025-07-21T00:00:00+00:00', '--job-id', '74', '--raw', '--subdir', 'DAGS_FOLDER/weather_dag.py', '--cfg-path', '/tmp/tmpjwbn7z5h']
[2025-07-21T07:41:15.590+0000] {standard_task_runner.py:91} INFO - Job 74: Subtask create_staging_table
[2025-07-21T07:41:15.591+0000] {logging_mixin.py:188} WARNING - /home/***/.local/lib/python3.12/site-packages/***/task/task_runner/standard_task_runner.py:61 DeprecationWarning: This process (pid=238) is multi-threaded, use of fork() may lead to deadlocks in the child.
[2025-07-21T07:41:15.591+0000] {standard_task_runner.py:63} INFO - Started process 240 to run task
[2025-07-21T07:41:15.634+0000] {task_command.py:426} INFO - Running <TaskInstance: fetch_weather_foreacst_dag.create_staging_table scheduled__2025-07-21T00:00:00+00:00 [running]> on host a689e5446531
[2025-07-21T07:41:15.706+0000] {taskinstance.py:2648} INFO - Exporting env vars: AIRFLOW_CTX_DAG_OWNER='***' AIRFLOW_CTX_DAG_ID='fetch_weather_foreacst_dag' AIRFLOW_CTX_TASK_ID='create_staging_table' AIRFLOW_CTX_EXECUTION_DATE='2025-07-21T00:00:00+00:00' AIRFLOW_CTX_TRY_NUMBER='2' AIRFLOW_CTX_DAG_RUN_ID='scheduled__2025-07-21T00:00:00+00:00'
[2025-07-21T07:41:15.707+0000] {taskinstance.py:430} INFO - ::endgroup::
[2025-07-21T07:41:23.721+0000] {taskinstance.py:441} INFO - ::group::Post task execution logs
[2025-07-21T07:41:23.722+0000] {taskinstance.py:2905} ERROR - Task failed with exception
Traceback (most recent call last):
  File "/home/airflow/.local/lib/python3.12/site-packages/mysql/connector/connection_cext.py", line 327, in _open_connection
    self._cmysql.connect(**cnx_kwargs)
_mysql_connector.MySQLInterfaceError: Unknown MySQL server host 'mysql' (-3)

The above exception was the direct cause of the following exception:

Traceback (most recent call last):
  File "/home/airflow/.local/lib/python3.12/site-packages/airflow/models/taskinstance.py", line 465, in _execute_task
    result = _execute_callable(context=context, **execute_callable_kwargs)
             ^^^^^^^^^^^^^^^^^^^^^^^^^^^^^^^^^^^^^^^^^^^^^^^^^^^^^^^^^^^^^
  File "/home/airflow/.local/lib/python3.12/site-packages/airflow/models/taskinstance.py", line 432, in _execute_callable
    return execute_callable(context=context, **execute_callable_kwargs)
           ^^^^^^^^^^^^^^^^^^^^^^^^^^^^^^^^^^^^^^^^^^^^^^^^^^^^^^^^^^^^
  File "/home/airflow/.local/lib/python3.12/site-packages/airflow/models/baseoperator.py", line 401, in wrapper
    return func(self, *args, **kwargs)
           ^^^^^^^^^^^^^^^^^^^^^^^^^^^
  File "/home/airflow/.local/lib/python3.12/site-packages/airflow/operators/python.py", line 235, in execute
    return_value = self.execute_callable()
                   ^^^^^^^^^^^^^^^^^^^^^^^
  File "/home/airflow/.local/lib/python3.12/site-packages/airflow/operators/python.py", line 252, in execute_callable
    return self.python_callable(*self.op_args, **self.op_kwargs)
           ^^^^^^^^^^^^^^^^^^^^^^^^^^^^^^^^^^^^^^^^^^^^^^^^^^^^^
  File "/opt/airflow/dags/weather_dag.py", line 25, in create_staging_table
    conn = mysql.connector.connect(
           ^^^^^^^^^^^^^^^^^^^^^^^^
  File "/home/airflow/.local/lib/python3.12/site-packages/mysql/connector/pooling.py", line 322, in connect
    return CMySQLConnection(*args, **kwargs)
           ^^^^^^^^^^^^^^^^^^^^^^^^^^^^^^^^^
  File "/home/airflow/.local/lib/python3.12/site-packages/mysql/connector/connection_cext.py", line 144, in __init__
    self.connect(**kwargs)
  File "/home/airflow/.local/lib/python3.12/site-packages/mysql/connector/abstracts.py", line 1360, in connect
    self._open_connection()
  File "/home/airflow/.local/lib/python3.12/site-packages/mysql/connector/connection_cext.py", line 332, in _open_connection
    raise get_mysql_exception(
mysql.connector.errors.DatabaseError: 2005 (HY000): Unknown MySQL server host 'mysql' (-3)
[2025-07-21T07:41:23.738+0000] {taskinstance.py:1206} INFO - Marking task as UP_FOR_RETRY. dag_id=fetch_weather_foreacst_dag, task_id=create_staging_table, run_id=scheduled__2025-07-21T00:00:00+00:00, execution_date=20250721T000000, start_date=20250721T074115, end_date=20250721T074123
[2025-07-21T07:41:23.752+0000] {standard_task_runner.py:110} ERROR - Failed to execute job 74 for task create_staging_table (2005 (HY000): Unknown MySQL server host 'mysql' (-3); 240)
[2025-07-21T07:41:23.764+0000] {local_task_job_runner.py:240} INFO - Task exited with return code 1
[2025-07-21T07:41:23.784+0000] {taskinstance.py:3503} INFO - 0 downstream tasks scheduled from follow-on schedule check
[2025-07-21T07:41:23.786+0000] {local_task_job_runner.py:222} INFO - ::endgroup::
