[2025-07-22T05:38:09.862+0000] {local_task_job_runner.py:120} INFO - ::group::Pre task execution logs
[2025-07-22T05:38:09.891+0000] {taskinstance.py:2076} INFO - Dependencies all met for dep_context=non-requeueable deps ti=<TaskInstance: weather_dag.transform_and_load manual__2025-07-22T05:32:52.416376+00:00 [queued]>
[2025-07-22T05:38:09.899+0000] {taskinstance.py:2076} INFO - Dependencies all met for dep_context=requeueable deps ti=<TaskInstance: weather_dag.transform_and_load manual__2025-07-22T05:32:52.416376+00:00 [queued]>
[2025-07-22T05:38:09.900+0000] {taskinstance.py:2306} INFO - Starting attempt 2 of 3
[2025-07-22T05:38:09.911+0000] {taskinstance.py:2330} INFO - Executing <Task(PythonOperator): transform_and_load> on 2025-07-22 05:32:52.416376+00:00
[2025-07-22T05:38:09.919+0000] {standard_task_runner.py:90} INFO - Running: ['***', 'tasks', 'run', 'weather_dag', 'transform_and_load', 'manual__2025-07-22T05:32:52.416376+00:00', '--job-id', '109', '--raw', '--subdir', 'DAGS_FOLDER/weather_dag.py', '--cfg-path', '/tmp/tmpsh7kebk8']
[2025-07-22T05:38:09.923+0000] {standard_task_runner.py:91} INFO - Job 109: Subtask transform_and_load
[2025-07-22T05:38:09.923+0000] {logging_mixin.py:188} WARNING - /home/***/.local/lib/python3.12/site-packages/***/task/task_runner/standard_task_runner.py:61 DeprecationWarning: This process (pid=250) is multi-threaded, use of fork() may lead to deadlocks in the child.
[2025-07-22T05:38:09.924+0000] {standard_task_runner.py:63} INFO - Started process 252 to run task
[2025-07-22T05:38:09.972+0000] {task_command.py:426} INFO - Running <TaskInstance: weather_dag.transform_and_load manual__2025-07-22T05:32:52.416376+00:00 [running]> on host 791cfe7304d9
[2025-07-22T05:38:10.047+0000] {taskinstance.py:2648} INFO - Exporting env vars: AIRFLOW_CTX_DAG_OWNER='***' AIRFLOW_CTX_DAG_ID='weather_dag' AIRFLOW_CTX_TASK_ID='transform_and_load' AIRFLOW_CTX_EXECUTION_DATE='2025-07-22T05:32:52.416376+00:00' AIRFLOW_CTX_TRY_NUMBER='2' AIRFLOW_CTX_DAG_RUN_ID='manual__2025-07-22T05:32:52.416376+00:00'
[2025-07-22T05:38:10.049+0000] {taskinstance.py:430} INFO - ::endgroup::
[2025-07-22T05:38:10.060+0000] {weather_dag.py:140} INFO - Bắt đầu transform và load dữ liệu
[2025-07-22T05:38:10.100+0000] {logging_mixin.py:188} WARNING - /opt/***/dags/weather_dag.py:150 UserWarning: pandas only supports SQLAlchemy connectable (engine/connection) or database string URI or sqlite3 DBAPI2 connection. Other DBAPI2 objects are not tested. Please consider using SQLAlchemy.
[2025-07-22T05:38:10.117+0000] {weather_dag.py:158} INFO - Xử lý dữ liệu...
[2025-07-22T05:38:10.133+0000] {taskinstance.py:441} INFO - ::group::Post task execution logs
[2025-07-22T05:38:10.133+0000] {taskinstance.py:2905} ERROR - Task failed with exception
Traceback (most recent call last):
  File "/home/airflow/.local/lib/python3.12/site-packages/airflow/models/taskinstance.py", line 465, in _execute_task
    result = _execute_callable(context=context, **execute_callable_kwargs)
             ^^^^^^^^^^^^^^^^^^^^^^^^^^^^^^^^^^^^^^^^^^^^^^^^^^^^^^^^^^^^^
  File "/home/airflow/.local/lib/python3.12/site-packages/airflow/models/taskinstance.py", line 432, in _execute_callable
    return execute_callable(context=context, **execute_callable_kwargs)
           ^^^^^^^^^^^^^^^^^^^^^^^^^^^^^^^^^^^^^^^^^^^^^^^^^^^^^^^^^^^^
  File "/home/airflow/.local/lib/python3.12/site-packages/airflow/models/baseoperator.py", line 401, in wrapper
    return func(self, *args, **kwargs)
           ^^^^^^^^^^^^^^^^^^^^^^^^^^^
  File "/home/airflow/.local/lib/python3.12/site-packages/airflow/operators/python.py", line 235, in execute
    return_value = self.execute_callable()
                   ^^^^^^^^^^^^^^^^^^^^^^^
  File "/home/airflow/.local/lib/python3.12/site-packages/airflow/operators/python.py", line 252, in execute_callable
    return self.python_callable(*self.op_args, **self.op_kwargs)
           ^^^^^^^^^^^^^^^^^^^^^^^^^^^^^^^^^^^^^^^^^^^^^^^^^^^^^
  File "/opt/airflow/dags/weather_dag.py", line 200, in transform_and_load
    cursor.execute(insert_query, values)
psycopg2.errors.UndefinedTable: relation "weather_db" does not exist
LINE 2:         INSERT INTO weather_db (
                            ^

[2025-07-22T05:38:10.146+0000] {taskinstance.py:1206} INFO - Marking task as UP_FOR_RETRY. dag_id=weather_dag, task_id=transform_and_load, run_id=manual__2025-07-22T05:32:52.416376+00:00, execution_date=20250722T053252, start_date=20250722T053809, end_date=20250722T053810
[2025-07-22T05:38:10.162+0000] {standard_task_runner.py:110} ERROR - Failed to execute job 109 for task transform_and_load (relation "weather_db" does not exist
LINE 2:         INSERT INTO weather_db (
                            ^
; 252)
[2025-07-22T05:38:10.178+0000] {local_task_job_runner.py:240} INFO - Task exited with return code 1
[2025-07-22T05:38:10.193+0000] {taskinstance.py:3503} INFO - 0 downstream tasks scheduled from follow-on schedule check
[2025-07-22T05:38:10.195+0000] {local_task_job_runner.py:222} INFO - ::endgroup::
