[2025-07-22T04:07:40.669+0000] {local_task_job_runner.py:120} INFO - ::group::Pre task execution logs
[2025-07-22T04:07:40.696+0000] {taskinstance.py:2076} INFO - Dependencies all met for dep_context=non-requeueable deps ti=<TaskInstance: weather_dag.transform_and_load scheduled__2025-07-21T18:00:00+00:00 [queued]>
[2025-07-22T04:07:40.704+0000] {taskinstance.py:2076} INFO - Dependencies all met for dep_context=requeueable deps ti=<TaskInstance: weather_dag.transform_and_load scheduled__2025-07-21T18:00:00+00:00 [queued]>
[2025-07-22T04:07:40.705+0000] {taskinstance.py:2306} INFO - Starting attempt 1 of 3
[2025-07-22T04:07:40.717+0000] {taskinstance.py:2330} INFO - Executing <Task(PythonOperator): transform_and_load> on 2025-07-21 18:00:00+00:00
[2025-07-22T04:07:40.724+0000] {standard_task_runner.py:90} INFO - Running: ['***', 'tasks', 'run', 'weather_dag', 'transform_and_load', 'scheduled__2025-07-21T18:00:00+00:00', '--job-id', '100', '--raw', '--subdir', 'DAGS_FOLDER/weather_dag.py', '--cfg-path', '/tmp/tmpqo7fi3yx']
[2025-07-22T04:07:40.727+0000] {standard_task_runner.py:91} INFO - Job 100: Subtask transform_and_load
[2025-07-22T04:07:40.727+0000] {logging_mixin.py:188} WARNING - /home/***/.local/lib/python3.12/site-packages/***/task/task_runner/standard_task_runner.py:61 DeprecationWarning: This process (pid=193) is multi-threaded, use of fork() may lead to deadlocks in the child.
[2025-07-22T04:07:40.728+0000] {standard_task_runner.py:63} INFO - Started process 197 to run task
[2025-07-22T04:07:40.768+0000] {task_command.py:426} INFO - Running <TaskInstance: weather_dag.transform_and_load scheduled__2025-07-21T18:00:00+00:00 [running]> on host 6a52d07e004b
[2025-07-22T04:07:40.840+0000] {taskinstance.py:2648} INFO - Exporting env vars: AIRFLOW_CTX_DAG_OWNER='***' AIRFLOW_CTX_DAG_ID='weather_dag' AIRFLOW_CTX_TASK_ID='transform_and_load' AIRFLOW_CTX_EXECUTION_DATE='2025-07-21T18:00:00+00:00' AIRFLOW_CTX_TRY_NUMBER='1' AIRFLOW_CTX_DAG_RUN_ID='scheduled__2025-07-21T18:00:00+00:00'
[2025-07-22T04:07:40.841+0000] {taskinstance.py:430} INFO - ::endgroup::
[2025-07-22T04:07:40.853+0000] {weather_dag.py:140} INFO - Bắt đầu transform và load dữ liệu
[2025-07-22T04:07:40.892+0000] {logging_mixin.py:188} WARNING - /opt/***/dags/weather_dag.py:150 UserWarning: pandas only supports SQLAlchemy connectable (engine/connection) or database string URI or sqlite3 DBAPI2 connection. Other DBAPI2 objects are not tested. Please consider using SQLAlchemy.
[2025-07-22T04:07:40.909+0000] {weather_dag.py:158} INFO - Xử lý dữ liệu...
[2025-07-22T04:07:40.936+0000] {taskinstance.py:441} INFO - ::group::Post task execution logs
[2025-07-22T04:07:40.937+0000] {taskinstance.py:2905} ERROR - Task failed with exception
Traceback (most recent call last):
  File "/home/airflow/.local/lib/python3.12/site-packages/airflow/models/taskinstance.py", line 465, in _execute_task
    result = _execute_callable(context=context, **execute_callable_kwargs)
             ^^^^^^^^^^^^^^^^^^^^^^^^^^^^^^^^^^^^^^^^^^^^^^^^^^^^^^^^^^^^^
  File "/home/airflow/.local/lib/python3.12/site-packages/airflow/models/taskinstance.py", line 432, in _execute_callable
    return execute_callable(context=context, **execute_callable_kwargs)
           ^^^^^^^^^^^^^^^^^^^^^^^^^^^^^^^^^^^^^^^^^^^^^^^^^^^^^^^^^^^^
  File "/home/airflow/.local/lib/python3.12/site-packages/airflow/models/baseoperator.py", line 401, in wrapper
    return func(self, *args, **kwargs)
           ^^^^^^^^^^^^^^^^^^^^^^^^^^^
  File "/home/airflow/.local/lib/python3.12/site-packages/airflow/operators/python.py", line 235, in execute
    return_value = self.execute_callable()
                   ^^^^^^^^^^^^^^^^^^^^^^^
  File "/home/airflow/.local/lib/python3.12/site-packages/airflow/operators/python.py", line 252, in execute_callable
    return self.python_callable(*self.op_args, **self.op_kwargs)
           ^^^^^^^^^^^^^^^^^^^^^^^^^^^^^^^^^^^^^^^^^^^^^^^^^^^^^
  File "/opt/airflow/dags/weather_dag.py", line 200, in transform_and_load
    cursor.execute(insert_query, values)
psycopg2.errors.UndefinedTable: relation "weather_dw.fact_weather" does not exist
LINE 2:         INSERT INTO weather_dw.fact_weather (
                            ^

[2025-07-22T04:07:40.948+0000] {taskinstance.py:1206} INFO - Marking task as UP_FOR_RETRY. dag_id=weather_dag, task_id=transform_and_load, run_id=scheduled__2025-07-21T18:00:00+00:00, execution_date=20250721T180000, start_date=20250722T040740, end_date=20250722T040740
[2025-07-22T04:07:40.962+0000] {standard_task_runner.py:110} ERROR - Failed to execute job 100 for task transform_and_load (relation "weather_dw.fact_weather" does not exist
LINE 2:         INSERT INTO weather_dw.fact_weather (
                            ^
; 197)
[2025-07-22T04:07:40.982+0000] {local_task_job_runner.py:240} INFO - Task exited with return code 1
[2025-07-22T04:07:40.998+0000] {taskinstance.py:3503} INFO - 0 downstream tasks scheduled from follow-on schedule check
[2025-07-22T04:07:41.001+0000] {local_task_job_runner.py:222} INFO - ::endgroup::
