[2025-07-22T04:12:41.970+0000] {local_task_job_runner.py:120} INFO - ::group::Pre task execution logs
[2025-07-22T04:12:42.000+0000] {taskinstance.py:2076} INFO - Dependencies all met for dep_context=non-requeueable deps ti=<TaskInstance: weather_dag.transform_and_load manual__2025-07-22T04:07:25.447697+00:00 [queued]>
[2025-07-22T04:12:42.008+0000] {taskinstance.py:2076} INFO - Dependencies all met for dep_context=requeueable deps ti=<TaskInstance: weather_dag.transform_and_load manual__2025-07-22T04:07:25.447697+00:00 [queued]>
[2025-07-22T04:12:42.010+0000] {taskinstance.py:2306} INFO - Starting attempt 2 of 3
[2025-07-22T04:12:42.020+0000] {taskinstance.py:2330} INFO - Executing <Task(PythonOperator): transform_and_load> on 2025-07-22 04:07:25.447697+00:00
[2025-07-22T04:12:42.029+0000] {standard_task_runner.py:90} INFO - Running: ['***', 'tasks', 'run', 'weather_dag', 'transform_and_load', 'manual__2025-07-22T04:07:25.447697+00:00', '--job-id', '101', '--raw', '--subdir', 'DAGS_FOLDER/weather_dag.py', '--cfg-path', '/tmp/tmph6xxtze_']
[2025-07-22T04:12:42.032+0000] {logging_mixin.py:188} WARNING - /home/***/.local/lib/python3.12/site-packages/***/task/task_runner/standard_task_runner.py:61 DeprecationWarning: This process (pid=259) is multi-threaded, use of fork() may lead to deadlocks in the child.
[2025-07-22T04:12:42.033+0000] {standard_task_runner.py:91} INFO - Job 101: Subtask transform_and_load
[2025-07-22T04:12:42.033+0000] {standard_task_runner.py:63} INFO - Started process 263 to run task
[2025-07-22T04:12:42.080+0000] {task_command.py:426} INFO - Running <TaskInstance: weather_dag.transform_and_load manual__2025-07-22T04:07:25.447697+00:00 [running]> on host 6a52d07e004b
[2025-07-22T04:12:42.150+0000] {taskinstance.py:2648} INFO - Exporting env vars: AIRFLOW_CTX_DAG_OWNER='***' AIRFLOW_CTX_DAG_ID='weather_dag' AIRFLOW_CTX_TASK_ID='transform_and_load' AIRFLOW_CTX_EXECUTION_DATE='2025-07-22T04:07:25.447697+00:00' AIRFLOW_CTX_TRY_NUMBER='2' AIRFLOW_CTX_DAG_RUN_ID='manual__2025-07-22T04:07:25.447697+00:00'
[2025-07-22T04:12:42.151+0000] {taskinstance.py:430} INFO - ::endgroup::
[2025-07-22T04:12:42.162+0000] {weather_dag.py:140} INFO - Bắt đầu transform và load dữ liệu
[2025-07-22T04:12:42.205+0000] {logging_mixin.py:188} WARNING - /opt/***/dags/weather_dag.py:150 UserWarning: pandas only supports SQLAlchemy connectable (engine/connection) or database string URI or sqlite3 DBAPI2 connection. Other DBAPI2 objects are not tested. Please consider using SQLAlchemy.
[2025-07-22T04:12:42.225+0000] {weather_dag.py:158} INFO - Xử lý dữ liệu...
[2025-07-22T04:12:42.240+0000] {taskinstance.py:441} INFO - ::group::Post task execution logs
[2025-07-22T04:12:42.241+0000] {taskinstance.py:2905} ERROR - Task failed with exception
Traceback (most recent call last):
  File "/home/airflow/.local/lib/python3.12/site-packages/airflow/models/taskinstance.py", line 465, in _execute_task
    result = _execute_callable(context=context, **execute_callable_kwargs)
             ^^^^^^^^^^^^^^^^^^^^^^^^^^^^^^^^^^^^^^^^^^^^^^^^^^^^^^^^^^^^^
  File "/home/airflow/.local/lib/python3.12/site-packages/airflow/models/taskinstance.py", line 432, in _execute_callable
    return execute_callable(context=context, **execute_callable_kwargs)
           ^^^^^^^^^^^^^^^^^^^^^^^^^^^^^^^^^^^^^^^^^^^^^^^^^^^^^^^^^^^^
  File "/home/airflow/.local/lib/python3.12/site-packages/airflow/models/baseoperator.py", line 401, in wrapper
    return func(self, *args, **kwargs)
           ^^^^^^^^^^^^^^^^^^^^^^^^^^^
  File "/home/airflow/.local/lib/python3.12/site-packages/airflow/operators/python.py", line 235, in execute
    return_value = self.execute_callable()
                   ^^^^^^^^^^^^^^^^^^^^^^^
  File "/home/airflow/.local/lib/python3.12/site-packages/airflow/operators/python.py", line 252, in execute_callable
    return self.python_callable(*self.op_args, **self.op_kwargs)
           ^^^^^^^^^^^^^^^^^^^^^^^^^^^^^^^^^^^^^^^^^^^^^^^^^^^^^
  File "/opt/airflow/dags/weather_dag.py", line 200, in transform_and_load
    cursor.execute(insert_query, values)
psycopg2.errors.UndefinedTable: relation "weather_dw.fact_weather" does not exist
LINE 2:         INSERT INTO weather_dw.fact_weather (
                            ^

[2025-07-22T04:12:42.253+0000] {taskinstance.py:1206} INFO - Marking task as UP_FOR_RETRY. dag_id=weather_dag, task_id=transform_and_load, run_id=manual__2025-07-22T04:07:25.447697+00:00, execution_date=20250722T040725, start_date=20250722T041242, end_date=20250722T041242
[2025-07-22T04:12:42.266+0000] {standard_task_runner.py:110} ERROR - Failed to execute job 101 for task transform_and_load (relation "weather_dw.fact_weather" does not exist
LINE 2:         INSERT INTO weather_dw.fact_weather (
                            ^
; 263)
[2025-07-22T04:12:42.287+0000] {local_task_job_runner.py:240} INFO - Task exited with return code 1
[2025-07-22T04:12:42.302+0000] {taskinstance.py:3503} INFO - 0 downstream tasks scheduled from follow-on schedule check
[2025-07-22T04:12:42.304+0000] {local_task_job_runner.py:222} INFO - ::endgroup::
