[2025-07-21T15:11:14.739+0000] {local_task_job_runner.py:120} INFO - ::group::Pre task execution logs
[2025-07-21T15:11:14.767+0000] {taskinstance.py:2076} INFO - Dependencies all met for dep_context=non-requeueable deps ti=<TaskInstance: fetch_weather_foreacst_dag.create_staging_table manual__2025-07-21T15:06:04.472443+00:00 [queued]>
[2025-07-21T15:11:14.776+0000] {taskinstance.py:2076} INFO - Dependencies all met for dep_context=requeueable deps ti=<TaskInstance: fetch_weather_foreacst_dag.create_staging_table manual__2025-07-21T15:06:04.472443+00:00 [queued]>
[2025-07-21T15:11:14.777+0000] {taskinstance.py:2306} INFO - Starting attempt 2 of 3
[2025-07-21T15:11:14.795+0000] {taskinstance.py:2330} INFO - Executing <Task(PythonOperator): create_staging_table> on 2025-07-21 15:06:04.472443+00:00
[2025-07-21T15:11:14.812+0000] {logging_mixin.py:188} WARNING - /home/***/.local/lib/python3.12/site-packages/***/task/task_runner/standard_task_runner.py:61 DeprecationWarning: This process (pid=316) is multi-threaded, use of fork() may lead to deadlocks in the child.
[2025-07-21T15:11:14.808+0000] {standard_task_runner.py:90} INFO - Running: ['***', 'tasks', 'run', 'fetch_weather_foreacst_dag', 'create_staging_table', 'manual__2025-07-21T15:06:04.472443+00:00', '--job-id', '86', '--raw', '--subdir', 'DAGS_FOLDER/weather_dag.py', '--cfg-path', '/tmp/tmpr2zd3ypj']
[2025-07-21T15:11:14.813+0000] {standard_task_runner.py:63} INFO - Started process 318 to run task
[2025-07-21T15:11:14.814+0000] {standard_task_runner.py:91} INFO - Job 86: Subtask create_staging_table
[2025-07-21T15:11:14.874+0000] {task_command.py:426} INFO - Running <TaskInstance: fetch_weather_foreacst_dag.create_staging_table manual__2025-07-21T15:06:04.472443+00:00 [running]> on host f5776ee018f1
[2025-07-21T15:11:14.976+0000] {taskinstance.py:2648} INFO - Exporting env vars: AIRFLOW_CTX_DAG_OWNER='***' AIRFLOW_CTX_DAG_ID='fetch_weather_foreacst_dag' AIRFLOW_CTX_TASK_ID='create_staging_table' AIRFLOW_CTX_EXECUTION_DATE='2025-07-21T15:06:04.472443+00:00' AIRFLOW_CTX_TRY_NUMBER='2' AIRFLOW_CTX_DAG_RUN_ID='manual__2025-07-21T15:06:04.472443+00:00'
[2025-07-21T15:11:14.978+0000] {taskinstance.py:430} INFO - ::endgroup::
[2025-07-21T15:11:23.000+0000] {taskinstance.py:441} INFO - ::group::Post task execution logs
[2025-07-21T15:11:23.001+0000] {taskinstance.py:2905} ERROR - Task failed with exception
Traceback (most recent call last):
  File "/home/airflow/.local/lib/python3.12/site-packages/mysql/connector/connection_cext.py", line 327, in _open_connection
    self._cmysql.connect(**cnx_kwargs)
_mysql_connector.MySQLInterfaceError: Unknown MySQL server host 'mysql' (-3)

The above exception was the direct cause of the following exception:

Traceback (most recent call last):
  File "/home/airflow/.local/lib/python3.12/site-packages/airflow/models/taskinstance.py", line 465, in _execute_task
    result = _execute_callable(context=context, **execute_callable_kwargs)
             ^^^^^^^^^^^^^^^^^^^^^^^^^^^^^^^^^^^^^^^^^^^^^^^^^^^^^^^^^^^^^
  File "/home/airflow/.local/lib/python3.12/site-packages/airflow/models/taskinstance.py", line 432, in _execute_callable
    return execute_callable(context=context, **execute_callable_kwargs)
           ^^^^^^^^^^^^^^^^^^^^^^^^^^^^^^^^^^^^^^^^^^^^^^^^^^^^^^^^^^^^
  File "/home/airflow/.local/lib/python3.12/site-packages/airflow/models/baseoperator.py", line 401, in wrapper
    return func(self, *args, **kwargs)
           ^^^^^^^^^^^^^^^^^^^^^^^^^^^
  File "/home/airflow/.local/lib/python3.12/site-packages/airflow/operators/python.py", line 235, in execute
    return_value = self.execute_callable()
                   ^^^^^^^^^^^^^^^^^^^^^^^
  File "/home/airflow/.local/lib/python3.12/site-packages/airflow/operators/python.py", line 252, in execute_callable
    return self.python_callable(*self.op_args, **self.op_kwargs)
           ^^^^^^^^^^^^^^^^^^^^^^^^^^^^^^^^^^^^^^^^^^^^^^^^^^^^^
  File "/opt/airflow/dags/weather_dag.py", line 26, in create_staging_table
    conn = mysql.connector.connect(
           ^^^^^^^^^^^^^^^^^^^^^^^^
  File "/home/airflow/.local/lib/python3.12/site-packages/mysql/connector/pooling.py", line 322, in connect
    return CMySQLConnection(*args, **kwargs)
           ^^^^^^^^^^^^^^^^^^^^^^^^^^^^^^^^^
  File "/home/airflow/.local/lib/python3.12/site-packages/mysql/connector/connection_cext.py", line 144, in __init__
    self.connect(**kwargs)
  File "/home/airflow/.local/lib/python3.12/site-packages/mysql/connector/abstracts.py", line 1360, in connect
    self._open_connection()
  File "/home/airflow/.local/lib/python3.12/site-packages/mysql/connector/connection_cext.py", line 332, in _open_connection
    raise get_mysql_exception(
mysql.connector.errors.DatabaseError: 2005 (HY000): Unknown MySQL server host 'mysql' (-3)
[2025-07-21T15:11:23.013+0000] {taskinstance.py:1206} INFO - Marking task as UP_FOR_RETRY. dag_id=fetch_weather_foreacst_dag, task_id=create_staging_table, run_id=manual__2025-07-21T15:06:04.472443+00:00, execution_date=20250721T150604, start_date=20250721T151114, end_date=20250721T151123
[2025-07-21T15:11:23.026+0000] {standard_task_runner.py:110} ERROR - Failed to execute job 86 for task create_staging_table (2005 (HY000): Unknown MySQL server host 'mysql' (-3); 318)
[2025-07-21T15:11:23.071+0000] {local_task_job_runner.py:240} INFO - Task exited with return code 1
[2025-07-21T15:11:23.092+0000] {taskinstance.py:3503} INFO - 0 downstream tasks scheduled from follow-on schedule check
[2025-07-21T15:11:23.094+0000] {local_task_job_runner.py:222} INFO - ::endgroup::
