[2025-07-20T20:20:08.462+0000] {local_task_job_runner.py:120} INFO - ::group::Pre task execution logs
[2025-07-20T20:20:08.488+0000] {taskinstance.py:2076} INFO - Dependencies all met for dep_context=non-requeueable deps ti=<TaskInstance: fetch_weather_forecast.load_staging_to_mysql manual__2025-07-20T20:09:51.612337+00:00 [queued]>
[2025-07-20T20:20:08.496+0000] {taskinstance.py:2076} INFO - Dependencies all met for dep_context=requeueable deps ti=<TaskInstance: fetch_weather_forecast.load_staging_to_mysql manual__2025-07-20T20:09:51.612337+00:00 [queued]>
[2025-07-20T20:20:08.497+0000] {taskinstance.py:2306} INFO - Starting attempt 3 of 3
[2025-07-20T20:20:08.508+0000] {taskinstance.py:2330} INFO - Executing <Task(PythonOperator): load_staging_to_mysql> on 2025-07-20 20:09:51.612337+00:00
[2025-07-20T20:20:08.516+0000] {standard_task_runner.py:90} INFO - Running: ['***', 'tasks', 'run', 'fetch_weather_forecast', 'load_staging_to_mysql', 'manual__2025-07-20T20:09:51.612337+00:00', '--job-id', '55', '--raw', '--subdir', 'DAGS_FOLDER/fetch_weather_data.py', '--cfg-path', '/tmp/tmp8njoon_h']
[2025-07-20T20:20:08.519+0000] {standard_task_runner.py:91} INFO - Job 55: Subtask load_staging_to_mysql
[2025-07-20T20:20:08.519+0000] {logging_mixin.py:188} WARNING - /home/***/.local/lib/python3.12/site-packages/***/task/task_runner/standard_task_runner.py:61 DeprecationWarning: This process (pid=370) is multi-threaded, use of fork() may lead to deadlocks in the child.
[2025-07-20T20:20:08.520+0000] {standard_task_runner.py:63} INFO - Started process 372 to run task
[2025-07-20T20:20:08.561+0000] {task_command.py:426} INFO - Running <TaskInstance: fetch_weather_forecast.load_staging_to_mysql manual__2025-07-20T20:09:51.612337+00:00 [running]> on host 3f0354c114aa
[2025-07-20T20:20:08.641+0000] {taskinstance.py:2648} INFO - Exporting env vars: AIRFLOW_CTX_DAG_OWNER='***' AIRFLOW_CTX_DAG_ID='fetch_weather_forecast' AIRFLOW_CTX_TASK_ID='load_staging_to_mysql' AIRFLOW_CTX_EXECUTION_DATE='2025-07-20T20:09:51.612337+00:00' AIRFLOW_CTX_TRY_NUMBER='3' AIRFLOW_CTX_DAG_RUN_ID='manual__2025-07-20T20:09:51.612337+00:00'
[2025-07-20T20:20:08.642+0000] {taskinstance.py:430} INFO - ::endgroup::
[2025-07-20T20:20:08.655+0000] {logging_mixin.py:188} INFO - ƒêang load file: /opt/***/data/weather_20250720_201003.csv
[2025-07-20T20:20:08.709+0000] {taskinstance.py:441} INFO - ::group::Post task execution logs
[2025-07-20T20:20:08.710+0000] {taskinstance.py:2905} ERROR - Task failed with exception
Traceback (most recent call last):
  File "/home/airflow/.local/lib/python3.12/site-packages/mysql/connector/connection_cext.py", line 697, in cmd_query
    self._cmysql.query(
_mysql_connector.MySQLInterfaceError: Unknown column 'nan' in 'field list'

The above exception was the direct cause of the following exception:

Traceback (most recent call last):
  File "/home/airflow/.local/lib/python3.12/site-packages/airflow/models/taskinstance.py", line 465, in _execute_task
    result = _execute_callable(context=context, **execute_callable_kwargs)
             ^^^^^^^^^^^^^^^^^^^^^^^^^^^^^^^^^^^^^^^^^^^^^^^^^^^^^^^^^^^^^
  File "/home/airflow/.local/lib/python3.12/site-packages/airflow/models/taskinstance.py", line 432, in _execute_callable
    return execute_callable(context=context, **execute_callable_kwargs)
           ^^^^^^^^^^^^^^^^^^^^^^^^^^^^^^^^^^^^^^^^^^^^^^^^^^^^^^^^^^^^
  File "/home/airflow/.local/lib/python3.12/site-packages/airflow/models/baseoperator.py", line 401, in wrapper
    return func(self, *args, **kwargs)
           ^^^^^^^^^^^^^^^^^^^^^^^^^^^
  File "/home/airflow/.local/lib/python3.12/site-packages/airflow/operators/python.py", line 235, in execute
    return_value = self.execute_callable()
                   ^^^^^^^^^^^^^^^^^^^^^^^
  File "/home/airflow/.local/lib/python3.12/site-packages/airflow/operators/python.py", line 252, in execute_callable
    return self.python_callable(*self.op_args, **self.op_kwargs)
           ^^^^^^^^^^^^^^^^^^^^^^^^^^^^^^^^^^^^^^^^^^^^^^^^^^^^^
  File "/opt/airflow/dags/load_to_staging_mysql.py", line 67, in load_staging_to_mysql
    cursor.execute(query, values)
  File "/home/airflow/.local/lib/python3.12/site-packages/mysql/connector/cursor_cext.py", line 372, in execute
    result = self._cnx.cmd_query(
             ^^^^^^^^^^^^^^^^^^^^
  File "/home/airflow/.local/lib/python3.12/site-packages/mysql/connector/opentelemetry/context_propagation.py", line 111, in wrapper
    result = method(cnx, *args, **kwargs)
             ^^^^^^^^^^^^^^^^^^^^^^^^^^^^
  File "/home/airflow/.local/lib/python3.12/site-packages/mysql/connector/connection_cext.py", line 705, in cmd_query
    raise get_mysql_exception(
mysql.connector.errors.ProgrammingError: 1054 (42S22): Unknown column 'nan' in 'field list'
[2025-07-20T20:20:08.734+0000] {taskinstance.py:1206} INFO - Marking task as FAILED. dag_id=fetch_weather_forecast, task_id=load_staging_to_mysql, run_id=manual__2025-07-20T20:09:51.612337+00:00, execution_date=20250720T200951, start_date=20250720T202008, end_date=20250720T202008
[2025-07-20T20:20:08.752+0000] {standard_task_runner.py:110} ERROR - Failed to execute job 55 for task load_staging_to_mysql (1054 (42S22): Unknown column 'nan' in 'field list'; 372)
[2025-07-20T20:20:08.775+0000] {local_task_job_runner.py:240} INFO - Task exited with return code 1
[2025-07-20T20:20:08.795+0000] {taskinstance.py:3503} INFO - 0 downstream tasks scheduled from follow-on schedule check
[2025-07-20T20:20:08.798+0000] {local_task_job_runner.py:222} INFO - ::endgroup::
